2023-12-12 17:30:20,240 (INFO) - django.utils.autoreload - Watching for file changes with StatReloader
2023-12-12 17:30:21,234 (WARNING) - silk.profiling.profiler - Cannot execute silk_profile as silk is not installed correctly.
2023-12-12 17:30:24,560 (WARNING) - django.request - Not Found: /favicon.ico
2023-12-12 17:30:30,669 (INFO) - playground.views - Calling httpbin
2023-12-12 17:30:32,948 (CRITICAL) - playground.views - Httpbin is offline
2023-12-12 17:30:36,478 (INFO) - playground.views - Calling httpbin
2023-12-12 17:30:41,336 (CRITICAL) - playground.views - Httpbin is offline
2023-12-12 17:30:57,331 (INFO) - django.utils.autoreload - C:\Users\Asus\Desktop\storefront\playground\views.py changed, reloading.
2023-12-12 17:30:58,146 (INFO) - django.utils.autoreload - Watching for file changes with StatReloader
2023-12-12 17:30:58,288 (WARNING) - silk.profiling.profiler - Cannot execute silk_profile as silk is not installed correctly.
2023-12-12 17:31:09,027 (INFO) - playground.views - Calling httpbin
2023-12-12 17:31:11,283 (CRITICAL) - playground.views - Httpbin is offline
2023-12-12 17:31:45,062 (INFO) - playground.views - Calling httpbin
2023-12-12 17:31:48,135 (CRITICAL) - playground.views - Httpbin is offline
2023-12-12 17:33:43,792 (INFO) - playground.views - Calling httpbin
2023-12-12 17:33:44,310 (CRITICAL) - playground.views - Httpbin is offline
2023-12-12 17:34:49,508 (INFO) - playground.views - Calling httpbin
2023-12-12 17:34:53,115 (INFO) - playground.views - Recieved the response
2023-12-12 17:56:28,194 (INFO) - django.utils.autoreload - C:\Users\Asus\Desktop\storefront\manage.py changed, reloading.
2023-12-12 17:58:54,777 (INFO) - django.utils.autoreload - Watching for file changes with StatReloader
2023-12-12 17:58:54,914 (WARNING) - silk.profiling.profiler - Cannot execute silk_profile as silk is not installed correctly.
2023-12-12 17:59:45,541 (WARNING) - django.request - Unauthorized: /store/collections/
2023-12-12 17:59:45,571 (WARNING) - django.request - Forbidden: /store/collections/
2023-12-12 17:59:45,576 (WARNING) - django.request - Bad Request: /store/collections/
2023-12-12 18:01:09,540 (INFO) - django.utils.autoreload - C:\Users\Asus\Desktop\storefront\storefront\settings\common.py changed, reloading.
2023-12-12 18:01:10,368 (INFO) - django.utils.autoreload - Watching for file changes with StatReloader
2023-12-12 18:01:10,516 (WARNING) - silk.profiling.profiler - Cannot execute silk_profile as silk is not installed correctly.
2023-12-12 18:01:13,665 (WARNING) - django.request - Unauthorized: /store/collections/
2023-12-12 18:01:13,693 (WARNING) - django.request - Forbidden: /store/collections/
2023-12-12 18:01:13,716 (WARNING) - django.request - Bad Request: /store/collections/
2023-12-21 12:48:33,448 (INFO) - django.utils.autoreload - Watching for file changes with StatReloader
2023-12-21 12:48:35,235 (WARNING) - silk.profiling.profiler - Cannot execute silk_profile as silk is not installed correctly.
2023-12-21 16:36:29,891 (INFO) - django.utils.autoreload - Watching for file changes with StatReloader
2023-12-21 16:36:31,329 (WARNING) - silk.profiling.profiler - Cannot execute silk_profile as silk is not installed correctly.
2023-12-21 16:39:19,338 (INFO) - django.utils.autoreload - C:\Users\Asus\Desktop\storefront\storefront\settings\dev.py changed, reloading.
2023-12-21 16:39:20,567 (INFO) - django.utils.autoreload - Watching for file changes with StatReloader
2023-12-21 16:39:20,738 (WARNING) - silk.profiling.profiler - Cannot execute silk_profile as silk is not installed correctly.
2023-12-21 16:40:10,034 (INFO) - django.utils.autoreload - C:\Users\Asus\Desktop\storefront\storefront\settings\common.py changed, reloading.
2023-12-21 16:40:11,569 (INFO) - django.utils.autoreload - Watching for file changes with StatReloader
2023-12-21 16:40:11,904 (WARNING) - silk.profiling.profiler - Cannot execute silk_profile as silk is not installed correctly.
2023-12-21 16:42:43,401 (INFO) - django.utils.autoreload - C:\Users\Asus\Desktop\storefront\storefront\settings\dev.py changed, reloading.
2023-12-21 16:42:44,682 (INFO) - django.utils.autoreload - Watching for file changes with StatReloader
2023-12-21 16:42:44,909 (WARNING) - silk.profiling.profiler - Cannot execute silk_profile as silk is not installed correctly.
2023-12-21 16:43:21,415 (INFO) - django.utils.autoreload - Watching for file changes with StatReloader
2023-12-21 16:43:21,574 (WARNING) - silk.profiling.profiler - Cannot execute silk_profile as silk is not installed correctly.
2023-12-21 16:43:41,335 (WARNING) - django.request - Not Found: /favicon.ico
2023-12-21 16:44:29,632 (INFO) - django.utils.autoreload - Watching for file changes with StatReloader
2023-12-21 16:44:29,777 (WARNING) - silk.profiling.profiler - Cannot execute silk_profile as silk is not installed correctly.
2023-12-21 15:04:57,987 (ERROR) - celery.utils.dispatch.signal - Signal handler <bound method DjangoFixup.on_import_modules of <celery.fixups.django.DjangoFixup object at 0x7f2e69dfef10>> raised: ModuleNotFoundError("No module named 'corsheaders'")
Traceback (most recent call last):
  File "/usr/local/lib/python3.11/site-packages/celery/utils/dispatch/signal.py", line 276, in send
    response = receiver(signal=self, sender=sender, **named)
               ^^^^^^^^^^^^^^^^^^^^^^^^^^^^^^^^^^^^^^^^^^^^^
  File "/usr/local/lib/python3.11/site-packages/celery/fixups/django.py", line 97, in on_import_modules
    self.worker_fixup.validate_models()
  File "/usr/local/lib/python3.11/site-packages/celery/fixups/django.py", line 135, in validate_models
    self.django_setup()
  File "/usr/local/lib/python3.11/site-packages/celery/fixups/django.py", line 131, in django_setup
    django.setup()
  File "/usr/local/lib/python3.11/site-packages/django/__init__.py", line 24, in setup
    apps.populate(settings.INSTALLED_APPS)
  File "/usr/local/lib/python3.11/site-packages/django/apps/registry.py", line 91, in populate
    app_config = AppConfig.create(entry)
                 ^^^^^^^^^^^^^^^^^^^^^^^
  File "/usr/local/lib/python3.11/site-packages/django/apps/config.py", line 193, in create
    import_module(entry)
  File "/usr/local/lib/python3.11/importlib/__init__.py", line 126, in import_module
    return _bootstrap._gcd_import(name[level:], package, level)
           ^^^^^^^^^^^^^^^^^^^^^^^^^^^^^^^^^^^^^^^^^^^^^^^^^^^^
  File "<frozen importlib._bootstrap>", line 1204, in _gcd_import
  File "<frozen importlib._bootstrap>", line 1176, in _find_and_load
  File "<frozen importlib._bootstrap>", line 1140, in _find_and_load_unlocked
ModuleNotFoundError: No module named 'corsheaders'
2023-12-21 15:04:57,990 (ERROR) - celery.utils.dispatch.signal - Signal handler <promise@0x7f2e69e20230 --> <bound method Celery._autodiscover_tasks of <Celery storefront at 0x7f2e69dfe990>>> raised: AppRegistryNotReady("Apps aren't loaded yet.")
Traceback (most recent call last):
  File "/usr/local/lib/python3.11/site-packages/celery/utils/dispatch/signal.py", line 276, in send
    response = receiver(signal=self, sender=sender, **named)
               ^^^^^^^^^^^^^^^^^^^^^^^^^^^^^^^^^^^^^^^^^^^^^
  File "/usr/local/lib/python3.11/site-packages/vine/promises.py", line 161, in __call__
    return self.throw()
           ^^^^^^^^^^^^
  File "/usr/local/lib/python3.11/site-packages/vine/promises.py", line 158, in __call__
    retval = fun(*final_args, **final_kwargs)
             ^^^^^^^^^^^^^^^^^^^^^^^^^^^^^^^^
  File "/usr/local/lib/python3.11/site-packages/celery/app/base.py", line 692, in _autodiscover_tasks
    return self._autodiscover_tasks_from_fixups(related_name)
           ^^^^^^^^^^^^^^^^^^^^^^^^^^^^^^^^^^^^^^^^^^^^^^^^^^
  File "/usr/local/lib/python3.11/site-packages/celery/app/base.py", line 701, in _autodiscover_tasks_from_fixups
    return self._autodiscover_tasks_from_names([
                                               ^
  File "/usr/local/lib/python3.11/site-packages/celery/app/base.py", line 704, in <listcomp>
    for pkg in fixup.autodiscover_tasks()
               ^^^^^^^^^^^^^^^^^^^^^^^^^^
  File "/usr/local/lib/python3.11/site-packages/celery/fixups/django.py", line 107, in autodiscover_tasks
    return [config.name for config in apps.get_app_configs()]
                                      ^^^^^^^^^^^^^^^^^^^^^^
  File "/usr/local/lib/python3.11/site-packages/django/apps/registry.py", line 147, in get_app_configs
    self.check_apps_ready()
  File "/usr/local/lib/python3.11/site-packages/django/apps/registry.py", line 138, in check_apps_ready
    raise AppRegistryNotReady("Apps aren't loaded yet.")
django.core.exceptions.AppRegistryNotReady: Apps aren't loaded yet.
2023-12-21 15:04:58,000 (ERROR) - celery.utils.dispatch.signal - Signal handler <bound method DjangoFixup.on_import_modules of <celery.fixups.django.DjangoFixup object at 0x7fe93bbea650>> raised: ModuleNotFoundError("No module named 'corsheaders'")
Traceback (most recent call last):
  File "/usr/local/lib/python3.11/site-packages/celery/utils/dispatch/signal.py", line 276, in send
    response = receiver(signal=self, sender=sender, **named)
               ^^^^^^^^^^^^^^^^^^^^^^^^^^^^^^^^^^^^^^^^^^^^^
  File "/usr/local/lib/python3.11/site-packages/celery/fixups/django.py", line 97, in on_import_modules
    self.worker_fixup.validate_models()
  File "/usr/local/lib/python3.11/site-packages/celery/fixups/django.py", line 135, in validate_models
    self.django_setup()
  File "/usr/local/lib/python3.11/site-packages/celery/fixups/django.py", line 131, in django_setup
    django.setup()
  File "/usr/local/lib/python3.11/site-packages/django/__init__.py", line 24, in setup
    apps.populate(settings.INSTALLED_APPS)
  File "/usr/local/lib/python3.11/site-packages/django/apps/registry.py", line 91, in populate
    app_config = AppConfig.create(entry)
                 ^^^^^^^^^^^^^^^^^^^^^^^
  File "/usr/local/lib/python3.11/site-packages/django/apps/config.py", line 193, in create
    import_module(entry)
  File "/usr/local/lib/python3.11/importlib/__init__.py", line 126, in import_module
    return _bootstrap._gcd_import(name[level:], package, level)
           ^^^^^^^^^^^^^^^^^^^^^^^^^^^^^^^^^^^^^^^^^^^^^^^^^^^^
  File "<frozen importlib._bootstrap>", line 1204, in _gcd_import
  File "<frozen importlib._bootstrap>", line 1176, in _find_and_load
  File "<frozen importlib._bootstrap>", line 1140, in _find_and_load_unlocked
ModuleNotFoundError: No module named 'corsheaders'
2023-12-21 15:04:58,002 (ERROR) - celery.utils.dispatch.signal - Signal handler <promise@0x7fe93bc08230 --> <bound method Celery._autodiscover_tasks of <Celery storefront at 0x7fe93bbe8f90>>> raised: AppRegistryNotReady("Apps aren't loaded yet.")
Traceback (most recent call last):
  File "/usr/local/lib/python3.11/site-packages/celery/utils/dispatch/signal.py", line 276, in send
    response = receiver(signal=self, sender=sender, **named)
               ^^^^^^^^^^^^^^^^^^^^^^^^^^^^^^^^^^^^^^^^^^^^^
  File "/usr/local/lib/python3.11/site-packages/vine/promises.py", line 161, in __call__
    return self.throw()
           ^^^^^^^^^^^^
  File "/usr/local/lib/python3.11/site-packages/vine/promises.py", line 158, in __call__
    retval = fun(*final_args, **final_kwargs)
             ^^^^^^^^^^^^^^^^^^^^^^^^^^^^^^^^
  File "/usr/local/lib/python3.11/site-packages/celery/app/base.py", line 692, in _autodiscover_tasks
    return self._autodiscover_tasks_from_fixups(related_name)
           ^^^^^^^^^^^^^^^^^^^^^^^^^^^^^^^^^^^^^^^^^^^^^^^^^^
  File "/usr/local/lib/python3.11/site-packages/celery/app/base.py", line 701, in _autodiscover_tasks_from_fixups
    return self._autodiscover_tasks_from_names([
                                               ^
  File "/usr/local/lib/python3.11/site-packages/celery/app/base.py", line 704, in <listcomp>
    for pkg in fixup.autodiscover_tasks()
               ^^^^^^^^^^^^^^^^^^^^^^^^^^
  File "/usr/local/lib/python3.11/site-packages/celery/fixups/django.py", line 107, in autodiscover_tasks
    return [config.name for config in apps.get_app_configs()]
                                      ^^^^^^^^^^^^^^^^^^^^^^
  File "/usr/local/lib/python3.11/site-packages/django/apps/registry.py", line 147, in get_app_configs
    self.check_apps_ready()
  File "/usr/local/lib/python3.11/site-packages/django/apps/registry.py", line 138, in check_apps_ready
    raise AppRegistryNotReady("Apps aren't loaded yet.")
django.core.exceptions.AppRegistryNotReady: Apps aren't loaded yet.
2023-12-21 18:09:34,283 (ERROR) - celery.utils.dispatch.signal - Signal handler <bound method DjangoFixup.on_import_modules of <celery.fixups.django.DjangoFixup object at 0x7f71b2586610>> raised: ModuleNotFoundError("No module named 'corsheaders'")
Traceback (most recent call last):
  File "/usr/local/lib/python3.11/site-packages/celery/utils/dispatch/signal.py", line 276, in send
    response = receiver(signal=self, sender=sender, **named)
               ^^^^^^^^^^^^^^^^^^^^^^^^^^^^^^^^^^^^^^^^^^^^^
  File "/usr/local/lib/python3.11/site-packages/celery/fixups/django.py", line 97, in on_import_modules
    self.worker_fixup.validate_models()
  File "/usr/local/lib/python3.11/site-packages/celery/fixups/django.py", line 135, in validate_models
    self.django_setup()
  File "/usr/local/lib/python3.11/site-packages/celery/fixups/django.py", line 131, in django_setup
    django.setup()
  File "/usr/local/lib/python3.11/site-packages/django/__init__.py", line 24, in setup
    apps.populate(settings.INSTALLED_APPS)
  File "/usr/local/lib/python3.11/site-packages/django/apps/registry.py", line 91, in populate
    app_config = AppConfig.create(entry)
                 ^^^^^^^^^^^^^^^^^^^^^^^
  File "/usr/local/lib/python3.11/site-packages/django/apps/config.py", line 193, in create
    import_module(entry)
  File "/usr/local/lib/python3.11/importlib/__init__.py", line 126, in import_module
    return _bootstrap._gcd_import(name[level:], package, level)
           ^^^^^^^^^^^^^^^^^^^^^^^^^^^^^^^^^^^^^^^^^^^^^^^^^^^^
  File "<frozen importlib._bootstrap>", line 1204, in _gcd_import
  File "<frozen importlib._bootstrap>", line 1176, in _find_and_load
  File "<frozen importlib._bootstrap>", line 1140, in _find_and_load_unlocked
ModuleNotFoundError: No module named 'corsheaders'
2023-12-21 18:09:34,283 (ERROR) - celery.utils.dispatch.signal - Signal handler <bound method DjangoFixup.on_import_modules of <celery.fixups.django.DjangoFixup object at 0x7f97887f2f10>> raised: ModuleNotFoundError("No module named 'corsheaders'")
Traceback (most recent call last):
  File "/usr/local/lib/python3.11/site-packages/celery/utils/dispatch/signal.py", line 276, in send
    response = receiver(signal=self, sender=sender, **named)
               ^^^^^^^^^^^^^^^^^^^^^^^^^^^^^^^^^^^^^^^^^^^^^
  File "/usr/local/lib/python3.11/site-packages/celery/fixups/django.py", line 97, in on_import_modules
    self.worker_fixup.validate_models()
  File "/usr/local/lib/python3.11/site-packages/celery/fixups/django.py", line 135, in validate_models
    self.django_setup()
  File "/usr/local/lib/python3.11/site-packages/celery/fixups/django.py", line 131, in django_setup
    django.setup()
  File "/usr/local/lib/python3.11/site-packages/django/__init__.py", line 24, in setup
    apps.populate(settings.INSTALLED_APPS)
  File "/usr/local/lib/python3.11/site-packages/django/apps/registry.py", line 91, in populate
    app_config = AppConfig.create(entry)
                 ^^^^^^^^^^^^^^^^^^^^^^^
  File "/usr/local/lib/python3.11/site-packages/django/apps/config.py", line 193, in create
    import_module(entry)
  File "/usr/local/lib/python3.11/importlib/__init__.py", line 126, in import_module
    return _bootstrap._gcd_import(name[level:], package, level)
           ^^^^^^^^^^^^^^^^^^^^^^^^^^^^^^^^^^^^^^^^^^^^^^^^^^^^
  File "<frozen importlib._bootstrap>", line 1204, in _gcd_import
  File "<frozen importlib._bootstrap>", line 1176, in _find_and_load
  File "<frozen importlib._bootstrap>", line 1140, in _find_and_load_unlocked
ModuleNotFoundError: No module named 'corsheaders'
2023-12-21 18:09:34,284 (ERROR) - celery.utils.dispatch.signal - Signal handler <promise@0x7f71b25a4230 --> <bound method Celery._autodiscover_tasks of <Celery storefront at 0x7f71b2586350>>> raised: AppRegistryNotReady("Apps aren't loaded yet.")
Traceback (most recent call last):
  File "/usr/local/lib/python3.11/site-packages/celery/utils/dispatch/signal.py", line 276, in send
    response = receiver(signal=self, sender=sender, **named)
               ^^^^^^^^^^^^^^^^^^^^^^^^^^^^^^^^^^^^^^^^^^^^^
  File "/usr/local/lib/python3.11/site-packages/vine/promises.py", line 161, in __call__
    return self.throw()
           ^^^^^^^^^^^^
  File "/usr/local/lib/python3.11/site-packages/vine/promises.py", line 158, in __call__
    retval = fun(*final_args, **final_kwargs)
             ^^^^^^^^^^^^^^^^^^^^^^^^^^^^^^^^
  File "/usr/local/lib/python3.11/site-packages/celery/app/base.py", line 692, in _autodiscover_tasks
    return self._autodiscover_tasks_from_fixups(related_name)
           ^^^^^^^^^^^^^^^^^^^^^^^^^^^^^^^^^^^^^^^^^^^^^^^^^^
  File "/usr/local/lib/python3.11/site-packages/celery/app/base.py", line 701, in _autodiscover_tasks_from_fixups
    return self._autodiscover_tasks_from_names([
                                               ^
  File "/usr/local/lib/python3.11/site-packages/celery/app/base.py", line 704, in <listcomp>
    for pkg in fixup.autodiscover_tasks()
               ^^^^^^^^^^^^^^^^^^^^^^^^^^
  File "/usr/local/lib/python3.11/site-packages/celery/fixups/django.py", line 107, in autodiscover_tasks
    return [config.name for config in apps.get_app_configs()]
                                      ^^^^^^^^^^^^^^^^^^^^^^
  File "/usr/local/lib/python3.11/site-packages/django/apps/registry.py", line 147, in get_app_configs
    self.check_apps_ready()
  File "/usr/local/lib/python3.11/site-packages/django/apps/registry.py", line 138, in check_apps_ready
    raise AppRegistryNotReady("Apps aren't loaded yet.")
django.core.exceptions.AppRegistryNotReady: Apps aren't loaded yet.
2023-12-21 18:09:34,284 (ERROR) - celery.utils.dispatch.signal - Signal handler <promise@0x7f9788814230 --> <bound method Celery._autodiscover_tasks of <Celery storefront at 0x7f97887f2990>>> raised: AppRegistryNotReady("Apps aren't loaded yet.")
Traceback (most recent call last):
  File "/usr/local/lib/python3.11/site-packages/celery/utils/dispatch/signal.py", line 276, in send
    response = receiver(signal=self, sender=sender, **named)
               ^^^^^^^^^^^^^^^^^^^^^^^^^^^^^^^^^^^^^^^^^^^^^
  File "/usr/local/lib/python3.11/site-packages/vine/promises.py", line 161, in __call__
    return self.throw()
           ^^^^^^^^^^^^
  File "/usr/local/lib/python3.11/site-packages/vine/promises.py", line 158, in __call__
    retval = fun(*final_args, **final_kwargs)
             ^^^^^^^^^^^^^^^^^^^^^^^^^^^^^^^^
  File "/usr/local/lib/python3.11/site-packages/celery/app/base.py", line 692, in _autodiscover_tasks
    return self._autodiscover_tasks_from_fixups(related_name)
           ^^^^^^^^^^^^^^^^^^^^^^^^^^^^^^^^^^^^^^^^^^^^^^^^^^
  File "/usr/local/lib/python3.11/site-packages/celery/app/base.py", line 701, in _autodiscover_tasks_from_fixups
    return self._autodiscover_tasks_from_names([
                                               ^
  File "/usr/local/lib/python3.11/site-packages/celery/app/base.py", line 704, in <listcomp>
    for pkg in fixup.autodiscover_tasks()
               ^^^^^^^^^^^^^^^^^^^^^^^^^^
  File "/usr/local/lib/python3.11/site-packages/celery/fixups/django.py", line 107, in autodiscover_tasks
    return [config.name for config in apps.get_app_configs()]
                                      ^^^^^^^^^^^^^^^^^^^^^^
  File "/usr/local/lib/python3.11/site-packages/django/apps/registry.py", line 147, in get_app_configs
    self.check_apps_ready()
  File "/usr/local/lib/python3.11/site-packages/django/apps/registry.py", line 138, in check_apps_ready
    raise AppRegistryNotReady("Apps aren't loaded yet.")
django.core.exceptions.AppRegistryNotReady: Apps aren't loaded yet.
2023-12-21 18:41:59,708 (ERROR) - celery.utils.dispatch.signal - Signal handler <bound method DjangoFixup.on_import_modules of <celery.fixups.django.DjangoFixup object at 0x7fafa0fd6610>> raised: ModuleNotFoundError("No module named 'corsheaders'")
Traceback (most recent call last):
  File "/usr/local/lib/python3.11/site-packages/celery/utils/dispatch/signal.py", line 276, in send
    response = receiver(signal=self, sender=sender, **named)
               ^^^^^^^^^^^^^^^^^^^^^^^^^^^^^^^^^^^^^^^^^^^^^
  File "/usr/local/lib/python3.11/site-packages/celery/fixups/django.py", line 97, in on_import_modules
    self.worker_fixup.validate_models()
  File "/usr/local/lib/python3.11/site-packages/celery/fixups/django.py", line 135, in validate_models
    self.django_setup()
  File "/usr/local/lib/python3.11/site-packages/celery/fixups/django.py", line 131, in django_setup
    django.setup()
  File "/usr/local/lib/python3.11/site-packages/django/__init__.py", line 24, in setup
    apps.populate(settings.INSTALLED_APPS)
  File "/usr/local/lib/python3.11/site-packages/django/apps/registry.py", line 91, in populate
    app_config = AppConfig.create(entry)
                 ^^^^^^^^^^^^^^^^^^^^^^^
  File "/usr/local/lib/python3.11/site-packages/django/apps/config.py", line 193, in create
    import_module(entry)
  File "/usr/local/lib/python3.11/importlib/__init__.py", line 126, in import_module
    return _bootstrap._gcd_import(name[level:], package, level)
           ^^^^^^^^^^^^^^^^^^^^^^^^^^^^^^^^^^^^^^^^^^^^^^^^^^^^
  File "<frozen importlib._bootstrap>", line 1204, in _gcd_import
  File "<frozen importlib._bootstrap>", line 1176, in _find_and_load
  File "<frozen importlib._bootstrap>", line 1140, in _find_and_load_unlocked
ModuleNotFoundError: No module named 'corsheaders'
2023-12-21 18:41:59,710 (ERROR) - celery.utils.dispatch.signal - Signal handler <promise@0x7fafa0ff4230 --> <bound method Celery._autodiscover_tasks of <Celery storefront at 0x7fafa0fd6350>>> raised: AppRegistryNotReady("Apps aren't loaded yet.")
Traceback (most recent call last):
  File "/usr/local/lib/python3.11/site-packages/celery/utils/dispatch/signal.py", line 276, in send
    response = receiver(signal=self, sender=sender, **named)
               ^^^^^^^^^^^^^^^^^^^^^^^^^^^^^^^^^^^^^^^^^^^^^
  File "/usr/local/lib/python3.11/site-packages/vine/promises.py", line 161, in __call__
    return self.throw()
           ^^^^^^^^^^^^
  File "/usr/local/lib/python3.11/site-packages/vine/promises.py", line 158, in __call__
    retval = fun(*final_args, **final_kwargs)
             ^^^^^^^^^^^^^^^^^^^^^^^^^^^^^^^^
  File "/usr/local/lib/python3.11/site-packages/celery/app/base.py", line 692, in _autodiscover_tasks
    return self._autodiscover_tasks_from_fixups(related_name)
           ^^^^^^^^^^^^^^^^^^^^^^^^^^^^^^^^^^^^^^^^^^^^^^^^^^
  File "/usr/local/lib/python3.11/site-packages/celery/app/base.py", line 701, in _autodiscover_tasks_from_fixups
    return self._autodiscover_tasks_from_names([
                                               ^
  File "/usr/local/lib/python3.11/site-packages/celery/app/base.py", line 704, in <listcomp>
    for pkg in fixup.autodiscover_tasks()
               ^^^^^^^^^^^^^^^^^^^^^^^^^^
  File "/usr/local/lib/python3.11/site-packages/celery/fixups/django.py", line 107, in autodiscover_tasks
    return [config.name for config in apps.get_app_configs()]
                                      ^^^^^^^^^^^^^^^^^^^^^^
  File "/usr/local/lib/python3.11/site-packages/django/apps/registry.py", line 147, in get_app_configs
    self.check_apps_ready()
  File "/usr/local/lib/python3.11/site-packages/django/apps/registry.py", line 138, in check_apps_ready
    raise AppRegistryNotReady("Apps aren't loaded yet.")
django.core.exceptions.AppRegistryNotReady: Apps aren't loaded yet.
2023-12-21 18:41:59,809 (ERROR) - celery.utils.dispatch.signal - Signal handler <bound method DjangoFixup.on_import_modules of <celery.fixups.django.DjangoFixup object at 0x7fb7da066610>> raised: ModuleNotFoundError("No module named 'corsheaders'")
Traceback (most recent call last):
  File "/usr/local/lib/python3.11/site-packages/celery/utils/dispatch/signal.py", line 276, in send
    response = receiver(signal=self, sender=sender, **named)
               ^^^^^^^^^^^^^^^^^^^^^^^^^^^^^^^^^^^^^^^^^^^^^
  File "/usr/local/lib/python3.11/site-packages/celery/fixups/django.py", line 97, in on_import_modules
    self.worker_fixup.validate_models()
  File "/usr/local/lib/python3.11/site-packages/celery/fixups/django.py", line 135, in validate_models
    self.django_setup()
  File "/usr/local/lib/python3.11/site-packages/celery/fixups/django.py", line 131, in django_setup
    django.setup()
  File "/usr/local/lib/python3.11/site-packages/django/__init__.py", line 24, in setup
    apps.populate(settings.INSTALLED_APPS)
  File "/usr/local/lib/python3.11/site-packages/django/apps/registry.py", line 91, in populate
    app_config = AppConfig.create(entry)
                 ^^^^^^^^^^^^^^^^^^^^^^^
  File "/usr/local/lib/python3.11/site-packages/django/apps/config.py", line 193, in create
    import_module(entry)
  File "/usr/local/lib/python3.11/importlib/__init__.py", line 126, in import_module
    return _bootstrap._gcd_import(name[level:], package, level)
           ^^^^^^^^^^^^^^^^^^^^^^^^^^^^^^^^^^^^^^^^^^^^^^^^^^^^
  File "<frozen importlib._bootstrap>", line 1204, in _gcd_import
  File "<frozen importlib._bootstrap>", line 1176, in _find_and_load
  File "<frozen importlib._bootstrap>", line 1140, in _find_and_load_unlocked
ModuleNotFoundError: No module named 'corsheaders'
2023-12-21 18:41:59,811 (ERROR) - celery.utils.dispatch.signal - Signal handler <promise@0x7fb7da084230 --> <bound method Celery._autodiscover_tasks of <Celery storefront at 0x7fb7da066350>>> raised: AppRegistryNotReady("Apps aren't loaded yet.")
Traceback (most recent call last):
  File "/usr/local/lib/python3.11/site-packages/celery/utils/dispatch/signal.py", line 276, in send
    response = receiver(signal=self, sender=sender, **named)
               ^^^^^^^^^^^^^^^^^^^^^^^^^^^^^^^^^^^^^^^^^^^^^
  File "/usr/local/lib/python3.11/site-packages/vine/promises.py", line 161, in __call__
    return self.throw()
           ^^^^^^^^^^^^
  File "/usr/local/lib/python3.11/site-packages/vine/promises.py", line 158, in __call__
    retval = fun(*final_args, **final_kwargs)
             ^^^^^^^^^^^^^^^^^^^^^^^^^^^^^^^^
  File "/usr/local/lib/python3.11/site-packages/celery/app/base.py", line 692, in _autodiscover_tasks
    return self._autodiscover_tasks_from_fixups(related_name)
           ^^^^^^^^^^^^^^^^^^^^^^^^^^^^^^^^^^^^^^^^^^^^^^^^^^
  File "/usr/local/lib/python3.11/site-packages/celery/app/base.py", line 701, in _autodiscover_tasks_from_fixups
    return self._autodiscover_tasks_from_names([
                                               ^
  File "/usr/local/lib/python3.11/site-packages/celery/app/base.py", line 704, in <listcomp>
    for pkg in fixup.autodiscover_tasks()
               ^^^^^^^^^^^^^^^^^^^^^^^^^^
  File "/usr/local/lib/python3.11/site-packages/celery/fixups/django.py", line 107, in autodiscover_tasks
    return [config.name for config in apps.get_app_configs()]
                                      ^^^^^^^^^^^^^^^^^^^^^^
  File "/usr/local/lib/python3.11/site-packages/django/apps/registry.py", line 147, in get_app_configs
    self.check_apps_ready()
  File "/usr/local/lib/python3.11/site-packages/django/apps/registry.py", line 138, in check_apps_ready
    raise AppRegistryNotReady("Apps aren't loaded yet.")
django.core.exceptions.AppRegistryNotReady: Apps aren't loaded yet.
2023-12-21 18:42:15,853 (INFO) - django.utils.autoreload - Watching for file changes with StatReloader
2023-12-21 19:08:00,585 (ERROR) - celery.utils.dispatch.signal - Signal handler <bound method DjangoFixup.on_import_modules of <celery.fixups.django.DjangoFixup object at 0x7f37cca3a650>> raised: ModuleNotFoundError("No module named 'corsheaders'")
Traceback (most recent call last):
  File "/usr/local/lib/python3.11/site-packages/celery/utils/dispatch/signal.py", line 276, in send
    response = receiver(signal=self, sender=sender, **named)
               ^^^^^^^^^^^^^^^^^^^^^^^^^^^^^^^^^^^^^^^^^^^^^
  File "/usr/local/lib/python3.11/site-packages/celery/fixups/django.py", line 97, in on_import_modules
    self.worker_fixup.validate_models()
  File "/usr/local/lib/python3.11/site-packages/celery/fixups/django.py", line 135, in validate_models
    self.django_setup()
  File "/usr/local/lib/python3.11/site-packages/celery/fixups/django.py", line 131, in django_setup
    django.setup()
  File "/usr/local/lib/python3.11/site-packages/django/__init__.py", line 24, in setup
    apps.populate(settings.INSTALLED_APPS)
  File "/usr/local/lib/python3.11/site-packages/django/apps/registry.py", line 91, in populate
    app_config = AppConfig.create(entry)
                 ^^^^^^^^^^^^^^^^^^^^^^^
  File "/usr/local/lib/python3.11/site-packages/django/apps/config.py", line 193, in create
    import_module(entry)
  File "/usr/local/lib/python3.11/importlib/__init__.py", line 126, in import_module
    return _bootstrap._gcd_import(name[level:], package, level)
           ^^^^^^^^^^^^^^^^^^^^^^^^^^^^^^^^^^^^^^^^^^^^^^^^^^^^
  File "<frozen importlib._bootstrap>", line 1204, in _gcd_import
  File "<frozen importlib._bootstrap>", line 1176, in _find_and_load
  File "<frozen importlib._bootstrap>", line 1140, in _find_and_load_unlocked
ModuleNotFoundError: No module named 'corsheaders'
2023-12-21 19:08:00,585 (ERROR) - celery.utils.dispatch.signal - Signal handler <bound method DjangoFixup.on_import_modules of <celery.fixups.django.DjangoFixup object at 0x7fc2e2b82ed0>> raised: ModuleNotFoundError("No module named 'corsheaders'")
Traceback (most recent call last):
  File "/usr/local/lib/python3.11/site-packages/celery/utils/dispatch/signal.py", line 276, in send
    response = receiver(signal=self, sender=sender, **named)
               ^^^^^^^^^^^^^^^^^^^^^^^^^^^^^^^^^^^^^^^^^^^^^
  File "/usr/local/lib/python3.11/site-packages/celery/fixups/django.py", line 97, in on_import_modules
    self.worker_fixup.validate_models()
  File "/usr/local/lib/python3.11/site-packages/celery/fixups/django.py", line 135, in validate_models
    self.django_setup()
  File "/usr/local/lib/python3.11/site-packages/celery/fixups/django.py", line 131, in django_setup
    django.setup()
  File "/usr/local/lib/python3.11/site-packages/django/__init__.py", line 24, in setup
    apps.populate(settings.INSTALLED_APPS)
  File "/usr/local/lib/python3.11/site-packages/django/apps/registry.py", line 91, in populate
    app_config = AppConfig.create(entry)
                 ^^^^^^^^^^^^^^^^^^^^^^^
  File "/usr/local/lib/python3.11/site-packages/django/apps/config.py", line 193, in create
    import_module(entry)
  File "/usr/local/lib/python3.11/importlib/__init__.py", line 126, in import_module
    return _bootstrap._gcd_import(name[level:], package, level)
           ^^^^^^^^^^^^^^^^^^^^^^^^^^^^^^^^^^^^^^^^^^^^^^^^^^^^
  File "<frozen importlib._bootstrap>", line 1204, in _gcd_import
  File "<frozen importlib._bootstrap>", line 1176, in _find_and_load
  File "<frozen importlib._bootstrap>", line 1140, in _find_and_load_unlocked
ModuleNotFoundError: No module named 'corsheaders'
2023-12-21 19:08:00,600 (ERROR) - celery.utils.dispatch.signal - Signal handler <promise@0x7fc2e2ba4230 --> <bound method Celery._autodiscover_tasks of <Celery storefront at 0x7fc2e2b82a10>>> raised: AppRegistryNotReady("Apps aren't loaded yet.")
Traceback (most recent call last):
  File "/usr/local/lib/python3.11/site-packages/celery/utils/dispatch/signal.py", line 276, in send
    response = receiver(signal=self, sender=sender, **named)
               ^^^^^^^^^^^^^^^^^^^^^^^^^^^^^^^^^^^^^^^^^^^^^
  File "/usr/local/lib/python3.11/site-packages/vine/promises.py", line 161, in __call__
    return self.throw()
           ^^^^^^^^^^^^
  File "/usr/local/lib/python3.11/site-packages/vine/promises.py", line 158, in __call__
    retval = fun(*final_args, **final_kwargs)
             ^^^^^^^^^^^^^^^^^^^^^^^^^^^^^^^^
  File "/usr/local/lib/python3.11/site-packages/celery/app/base.py", line 692, in _autodiscover_tasks
    return self._autodiscover_tasks_from_fixups(related_name)
           ^^^^^^^^^^^^^^^^^^^^^^^^^^^^^^^^^^^^^^^^^^^^^^^^^^
  File "/usr/local/lib/python3.11/site-packages/celery/app/base.py", line 701, in _autodiscover_tasks_from_fixups
    return self._autodiscover_tasks_from_names([
                                               ^
  File "/usr/local/lib/python3.11/site-packages/celery/app/base.py", line 704, in <listcomp>
    for pkg in fixup.autodiscover_tasks()
               ^^^^^^^^^^^^^^^^^^^^^^^^^^
  File "/usr/local/lib/python3.11/site-packages/celery/fixups/django.py", line 107, in autodiscover_tasks
    return [config.name for config in apps.get_app_configs()]
                                      ^^^^^^^^^^^^^^^^^^^^^^
  File "/usr/local/lib/python3.11/site-packages/django/apps/registry.py", line 147, in get_app_configs
    self.check_apps_ready()
  File "/usr/local/lib/python3.11/site-packages/django/apps/registry.py", line 138, in check_apps_ready
    raise AppRegistryNotReady("Apps aren't loaded yet.")
django.core.exceptions.AppRegistryNotReady: Apps aren't loaded yet.
2023-12-21 19:08:00,600 (ERROR) - celery.utils.dispatch.signal - Signal handler <promise@0x7f37cca58230 --> <bound method Celery._autodiscover_tasks of <Celery storefront at 0x7f37cca38f90>>> raised: AppRegistryNotReady("Apps aren't loaded yet.")
Traceback (most recent call last):
  File "/usr/local/lib/python3.11/site-packages/celery/utils/dispatch/signal.py", line 276, in send
    response = receiver(signal=self, sender=sender, **named)
               ^^^^^^^^^^^^^^^^^^^^^^^^^^^^^^^^^^^^^^^^^^^^^
  File "/usr/local/lib/python3.11/site-packages/vine/promises.py", line 161, in __call__
    return self.throw()
           ^^^^^^^^^^^^
  File "/usr/local/lib/python3.11/site-packages/vine/promises.py", line 158, in __call__
    retval = fun(*final_args, **final_kwargs)
             ^^^^^^^^^^^^^^^^^^^^^^^^^^^^^^^^
  File "/usr/local/lib/python3.11/site-packages/celery/app/base.py", line 692, in _autodiscover_tasks
    return self._autodiscover_tasks_from_fixups(related_name)
           ^^^^^^^^^^^^^^^^^^^^^^^^^^^^^^^^^^^^^^^^^^^^^^^^^^
  File "/usr/local/lib/python3.11/site-packages/celery/app/base.py", line 701, in _autodiscover_tasks_from_fixups
    return self._autodiscover_tasks_from_names([
                                               ^
  File "/usr/local/lib/python3.11/site-packages/celery/app/base.py", line 704, in <listcomp>
    for pkg in fixup.autodiscover_tasks()
               ^^^^^^^^^^^^^^^^^^^^^^^^^^
  File "/usr/local/lib/python3.11/site-packages/celery/fixups/django.py", line 107, in autodiscover_tasks
    return [config.name for config in apps.get_app_configs()]
                                      ^^^^^^^^^^^^^^^^^^^^^^
  File "/usr/local/lib/python3.11/site-packages/django/apps/registry.py", line 147, in get_app_configs
    self.check_apps_ready()
  File "/usr/local/lib/python3.11/site-packages/django/apps/registry.py", line 138, in check_apps_ready
    raise AppRegistryNotReady("Apps aren't loaded yet.")
django.core.exceptions.AppRegistryNotReady: Apps aren't loaded yet.
2023-12-21 19:08:30,419 (INFO) - django.utils.autoreload - Watching for file changes with StatReloader
2023-12-24 23:49:27,391 (INFO) - django.utils.autoreload - Watching for file changes with StatReloader
2023-12-24 23:49:28,928 (WARNING) - silk.profiling.profiler - Cannot execute silk_profile as silk is not installed correctly.
2023-12-24 23:50:14,792 (INFO) - django.utils.autoreload - Watching for file changes with StatReloader
2023-12-24 23:50:14,944 (WARNING) - silk.profiling.profiler - Cannot execute silk_profile as silk is not installed correctly.
2023-12-24 20:22:21,985 (INFO) - django.utils.autoreload - Watching for file changes with StatReloader
2023-12-25 23:15:04,390 (INFO) - django.utils.autoreload - Watching for file changes with StatReloader
2023-12-25 23:15:05,761 (WARNING) - silk.profiling.profiler - Cannot execute silk_profile as silk is not installed correctly.
2023-12-26 00:19:52,818 (INFO) - django.utils.autoreload - Watching for file changes with StatReloader
2023-12-26 00:19:53,021 (WARNING) - silk.profiling.profiler - Cannot execute silk_profile as silk is not installed correctly.
2023-12-26 00:21:39,657 (INFO) - django.utils.autoreload - Watching for file changes with StatReloader
2023-12-26 00:21:39,805 (WARNING) - silk.profiling.profiler - Cannot execute silk_profile as silk is not installed correctly.
2023-12-26 14:57:51,165 (INFO) - django.utils.autoreload - Watching for file changes with StatReloader
2023-12-26 14:57:52,652 (WARNING) - silk.profiling.profiler - Cannot execute silk_profile as silk is not installed correctly.
